Workbook
Name Slicer_countryname: #N/A
Name Slicer_Year_Opening: #N/A

Sheet Main
A1: RestaurantID | B1: RestaurantName | C1: CountryCode | D1: City | E1: Address | F1: Locality | G1: LocalityVerbose | H1: Longitude | I1: Latitude | J1: Cuisines | K1: Currency | L1: Has_Table_booking | M1: Has_Online_delivery | N1: Is_delivering_now | O1: Switch_to_order_menu | P1: Price_range | Q1: Votes | R1: Average_Cost_for_two | S1: Price_Bucket | T1: Rating | U1: Year Opening | V1: Month Opening | W1: Day Opening | X1: Datekey_Opening | Y1: Average_Cost_for_two_USD | Z1: countryname | AA1: Quarter
A2: 18435314 | B2: Punjabi's Veg Grill | C2: 1 | D2: New Delhi | E2: 13/288 , 14 Block Gurudwra, Geeta Colony, New Delhi | F2: Geeta Colony | G2: Geeta Colony, New Delhi | H2: 77.276769 | I2: 28.650775 | J2: North Indian | K2: Indian Rupees(Rs.) | L2: No | M2: No | N2: No | O2: No | P2: 1 | Q2: 0 | R2: 300 | S2: =IF(Table1[[#This Row],[Average_Cost_for_two]]<500,"Low",IF(Table1[[#This Row],[Average_Cost_for_two]]<=1500,"Medium","High")) -> Low | T2: 1 | U2: 2013 | V2: 9 | W2: 21 | X2: =IF(OR(Main!$U2=0, Main!$V2=0, Main!$W2=0), "", DATE(Main!$U2, Main!$V2, Main!$W2) ) -> 41538 | Y2: =Table1[[#This Row],[Average_Cost_for_two]]*VLOOKUP(Table1[[#This Row],[Currency]],currency!$A$2:$B$10,2,FALSE) -> 3.6 | Z2: =VLOOKUP(C2,country!A:B,2,FALSE) -> India | AA2: =ROUNDUP(V2/3,0) -> 3
A3: 18378015 | B3: Tasty Tandoor | C3: 1 | D3: New Delhi | E3: 726/2, Jheel Khuranja, Geeta Colony, New Delhi | F3: Geeta Colony | G3: Geeta Colony, New Delhi | H3: 77.275052 | I3: 28.658216 | J3: North Indian | K3: Indian Rupees(Rs.) | L3: No | M3: No | N3: No | O3: No | P3: 1 | Q3: 0 | R3: 200 | S3: =IF(Table1[[#This Row],[Average_Cost_for_two]]<500,"Low",IF(Table1[[#This Row],[Average_Cost_for_two]]<=1500,"Medium","High")) -> Low | T3: 1 | U3: 2016 | V3: 9 | W3: 10 | X3: =IF(OR(Main!$U3=0, Main!$V3=0, Main!$W3=0), "", DATE(Main!$U3, Main!$V3, Main!$W3) ) -> 42623 | Y3: =Table1[[#This Row],[Average_Cost_for_two]]*VLOOKUP(Table1[[#This Row],[Currency]],currency!$A$2:$B$10,2,FALSE) -> 2.4 | Z3: =VLOOKUP(C3,country!A:B,2,FALSE) -> India | AA3: =ROUNDUP(V3/3,0) -> 3
A4: 18424905 | B4: Taste of Spice | C4: 1 | D4: New Delhi | E4: C-222, Lajpat Nagar 1, New Delhi | F4: Lajpat Nagar 1 | G4: Lajpat Nagar 1, New Delhi | H4: 77.241312 | I4: 28.578311 | J4: North Indian | K4: Indian Rupees(Rs.) | L4: No | M4: Yes | N4: No | O4: No | P4: 1 | Q4: 0 | R4: 400 | S4: =IF(Table1[[#This Row],[Average_Cost_for_two]]<500,"Low",IF(Table1[[#This Row],[Average_Cost_for_two]]<=1500,"Medium","High")) -> Low | T4: 1 | U4: 2018 | V4: 9 | W4: 25 | X4: =IF(OR(Main!$U4=0, Main!$V4=0, Main!$W4=0), "", DATE(Main!$U4, Main!$V4, Main!$W4) ) -> 43368 | Y4: =Table1[[#This Row],[Average_Cost_for_two]]*VLOOKUP(Table1[[#This Row],[Currency]],currency!$A$2:$B$10,2,FALSE) -> 4.8 | Z4: =VLOOKUP(C4,country!A:B,2,FALSE) -> India | AA4: =ROUNDUP(V4/3,0) -> 3
A5: 18180072 | B5: Kolcata Bengali Dhaba | C5: 1 | D5: New Delhi | E5: Gali 7, Mahipalpur, New Delhi | F5: Mahipalpur | G5: Mahipalpur, New Delhi | H5: 77.123932 | I5: 28.543587 | J5: North Indian | K5: Indian Rupees(Rs.) | L5: No | M5: No | N5: No | O5: No | P5: 1 | Q5: 0 | R5: 100 | S5: =IF(Table1[[#This Row],[Average_Cost_for_two]]<500,"Low",IF(Table1[[#This Row],[Average_Cost_for_two]]<=1500,"Medium","High")) -> Low | T5: 1 | U5: 2018 | V5: 9 | W5: 6 | X5: =IF(OR(Main!$U5=0, Main!$V5=0, Main!$W5=0), "", DATE(Main!$U5, Main!$V5, Main!$W5) ) -> 43349 | Y5: =Table1[[#This Row],[Average_Cost_for_two]]*VLOOKUP(Table1[[#This Row],[Currency]],currency!$A$2:$B$10,2,FALSE) -> 1.2 | Z5: =VLOOKUP(C5,country!A:B,2,FALSE) -> India | AA5: =ROUNDUP(V5/3,0) -> 3
A6: 18415377 | B6: Sunil Punjabi Dhaba | C6: 1 | D6: New Delhi | E6: Main Vasant Kunj Road, Mahipalpur, New Delhi | F6: Mahipalpur | G6: Mahipalpur, New Delhi | H6: 77.129706 | I6: 28.541369 | J6: North Indian | K6: Indian Rupees(Rs.) | L6: No | M6: No | N6: No | O6: No | P6: 1 | Q6: 0 | R6: 150 | S6: =IF(Table1[[#This Row],[Average_Cost_for_two]]<500,"Low",IF(Table1[[#This Row],[Average_Cost_for_two]]<=1500,"Medium","High")) -> Low | T6: 1 | U6: 2013 | V6: 9 | W6: 17 | X6: =IF(OR(Main!$U6=0, Main!$V6=0, Main!$W6=0), "", DATE(Main!$U6, Main!$V6, Main!$W6) ) -> 41534 | Y6: =Table1[[#This Row],[Average_Cost_for_two]]*VLOOKUP(Table1[[#This Row],[Currency]],currency!$A$2:$B$10,2,FALSE) -> 1.8 | Z6: =VLOOKUP(C6,country!A:B,2,FALSE) -> India | AA6: =ROUNDUP(V6/3,0) -> 3
A7: 18421485 | B7: Bikaner Restaurant | C7: 1 | D7: New Delhi | E7: Shop 264, Near Hakikat Nagar, Mukherjee Nagar, New Delhi | F7: Mukherjee Nagar | G7: Mukherjee Nagar, New Delhi | H7: 77.208135 | I7: 28.699566 | J7: North Indian | K7: Indian Rupees(Rs.) | L7: No | M7: No | N7: No | O7: No | P7: 1 | Q7: 0 | R7: 100 | S7: =IF(Table1[[#This Row],[Average_Cost_for_two]]<500,"Low",IF(Table1[[#This Row],[Average_Cost_for_two]]<=1500,"Medium","High")) -> Low | T7: 1 | U7: 2018 | V7: 9 | W7: 3 | X7: =IF(OR(Main!$U7=0, Main!$V7=0, Main!$W7=0), "", DATE(Main!$U7, Main!$V7, Main!$W7) ) -> 43346 | Y7: =Table1[[#This Row],[Average_Cost_for_two]]*VLOOKUP(Table1[[#This Row],[Currency]],currency!$A$2:$B$10,2,FALSE) -> 1.2 | Z7: =VLOOKUP(C7,country!A:B,2,FALSE) -> India | AA7: =ROUNDUP(V7/3,0) -> 3
A8: 312413 | B8: Just In | C8: 1 | D8: New Delhi | E8: G-103, Vardhaman Mall, Mukherjee Nagar, New Delhi | F8: Mukherjee Nagar | G8: Mukherjee Nagar, New Delhi | H8: 77.219094 | I8: 28.70948 | J8: North Indian | K8: Indian Rupees(Rs.) | L8: No | M8: No | N8: No | O8: No | P8: 1 | Q8: 0 | R8: 200 | S8: =IF(Table1[[#This Row],[Average_Cost_for_two]]<500,"Low",IF(Table1[[#This Row],[Average_Cost_for_two]]<=1500,"Medium","High")) -> Low | T8: 1 | U8: 2011 | V8: 9 | W8: 16 | X8: =IF(OR(Main!$U8=0, Main!$V8=0, Main!$W8=0), "", DATE(Main!$U8, Main!$V8, Main!$W8) ) -> 40802 | Y8: =Table1[[#This Row],[Average_Cost_for_two]]*VLOOKUP(Table1[[#This Row],[Currency]],currency!$A$2:$B$10,2,FALSE) -> 2.4 | Z8: =VLOOKUP(C8,country!A:B,2,FALSE) -> India | AA8: =ROUNDUP(V8/3,0) -> 3
A9: 303497 | B9: Shri Shyam Ji Shudh Shakahari Bhojnalaya | C9: 1 | D9: New Delhi | E9: Khaira Mod, Najafgarh, New Delhi | F9: Najafgarh | G9: Najafgarh, New Delhi | H9: 76.974892 | I9: 28.611254 | J9: North Indian | K9: Indian Rupees(Rs.) | L9: No | M9: No | N9: No | O9: No | P9: 1 | Q9: 0 | R9: 150 | S9: =IF(Table1[[#This Row],[Average_Cost_for_two]]<500,"Low",IF(Table1[[#This Row],[Average_Cost_for_two]]<=1500,"Medium","High")) -> Low | T9: 1 | U9: 2014 | V9: 9 | W9: 21 | X9: =IF(OR(Main!$U9=0, Main!$V9=0, Main!$W9=0), "", DATE(Main!$U9, Main!$V9, Main!$W9) ) -> 41903 | Y9: =Table1[[#This Row],[Average_Cost_for_two]]*VLOOKUP(Table1[[#This Row],[Currency]],currency!$A$2:$B$10,2,FALSE) -> 1.8 | Z9: =VLOOKUP(C9,country!A:B,2,FALSE) -> India | AA9: =ROUNDUP(V9/3,0) -> 3
A10: 18354644 | B10: Shree Bhojnalaya | C10: 1 | D10: New Delhi | E10: Sarai Julena, Near Red Light, New Friends Colony, New Delhi | F10: New Friends Colony | G10: New Friends Colony, New Delhi | H10: 77.272762 | I10: 28.560771 | J10: North Indian | K10: Indian Rupees(Rs.) | L10: No | M10: No | N10: No | O10: No | P10: 1 | Q10: 0 | R10: 100 | S10: =IF(Table1[[#This Row],[Average_Cost_for_two]]<500,"Low",IF(Table1[[#This Row],[Average_Cost_for_two]]<=1500,"Medium","High")) -> Low | T10: 1 | U10: 2012 | V10: 9 | W10: 9 | X10: =IF(OR(Main!$U10=0, Main!$V10=0, Main!$W10=0), "", DATE(Main!$U10, Main!$V10, Main!$W10) ) -> 41161 | Y10: =Table1[[#This Row],[Average_Cost_for_two]]*VLOOKUP(Table1[[#This Row],[Currency]],currency!$A$2:$B$10,2,FALSE) -> 1.2 | Z10: =VLOOKUP(C10,country!A:B,2,FALSE) -> India | AA10: =ROUNDUP(V10/3,0) -> 3
A11: 18366001 | B11: Baba Ka Dhaba | C11: 1 | D11: New Delhi | E11: WZ-425, Main Road, Palam Colony, Opposite Railway Crossing, Palam, New Delhi | F11: Palam | G11: Palam, New Delhi | H11: 77.09028 | I11: 28.582898 | J11: North Indian | K11: Indian Rupees(Rs.) | L11: No | M11: No | N11: No | O11: No | P11: 1 | Q11: 0 | R11: 200 | S11: =IF(Table1[[#This Row],[Average_Cost_for_two]]<500,"Low",IF(Table1[[#This Row],[Average_Cost_for_two]]<=1500,"Medium","High")) -> Low | T11: 1 | U11: 2014 | V11: 9 | W11: 21 | X11: =IF(OR(Main!$U11=0, Main!$V11=0, Main!$W11=0), "", DATE(Main!$U11, Main!$V11, Main!$W11) ) -> 41903 | Y11: =Table1[[#This Row],[Average_Cost_for_two]]*VLOOKUP(Table1[[#This Row],[Currency]],currency!$A$2:$B$10,2,FALSE) -> 2.4 | Z11: =VLOOKUP(C11,country!A:B,2,FALSE) -> India | AA11: =ROUNDUP(V11/3,0) -> 3
A12: 18486845 | B12: Kaka Da Dhaba | C12: 1 | D12: New Delhi | E12: R.K. Puram Sector 12, R K Puram, New Delhi | F12: R K Puram | G12: R K Puram, New Delhi | H12: 77.174118 | I12: 28.577193 | J12: North Indian | K12: Indian Rupees(Rs.) | L12: No | M12: No | N12: No | O12: No | P12: 1 | Q12: 0 | R12: 100 | S12: =IF(Table1[[#This Row],[Average_Cost_for_two]]<500,"Low",IF(Table1[[#This Row],[Average_Cost_for_two]]<=1500,"Medium","High")) -> Low | T12: 1 | U12: 2012 | V12: 9 | W12: 24 | X12: =IF(OR(Main!$U12=0, Main!$V12=0, Main!$W12=0), "", DATE(Main!$U12, Main!$V12, Main!$W12) ) -> 41176 | Y12: =Table1[[#This Row],[Average_Cost_for_two]]*VLOOKUP(Table1[[#This Row],[Currency]],currency!$A$2:$B$10,2,FALSE) -> 1.2 | Z12: =VLOOKUP(C12,country!A:B,2,FALSE) -> India | AA12: =ROUNDUP(V12/3,0) -> 3
A13: 18424202 | B13: Famous Parantha and Poori Sabzi | C13: 1 | D13: New Delhi | E13: 44, Gali Number 1, Block A, New Ashok Nagar, Vasundhara Enclave, New Delhi | F13: Vasundhara Enclave | G13: Vasundhara Enclave, New Delhi | H13: 77.308509 | I13: 28.589376 | J13: North Indian | K13: Indian Rupees(Rs.) | L13: No | M13: No | N13: No | O13: No | P13: 1 | Q13: 0 | R13: 50 | S13: =IF(Table1[[#This Row],[Average_Cost_for_two]]<500,"Low",IF(Table1[[#This Row],[Average_Cost_for_two]]<=1500,"Medium","High")) -> Low | T13: 1 | U13: 2014 | V13: 9 | W13: 20 | X13: =IF(OR(Main!$U13=0, Main!$V13=0, Main!$W13=0), "", DATE(Main!$U13, Main!$V13, Main!$W13) ) -> 41902 | Y13: =Table1[[#This Row],[Average_Cost_for_two]]*VLOOKUP(Table1[[#This Row],[Currency]],currency!$A$2:$B$10,2,FALSE) -> 0.6 | Z13: =VLOOKUP(C13,country!A:B,2,FALSE) -> India | AA13: =ROUNDUP(V13/3,0) -> 3
... A8067: 49003 | B8067: SpiceKlub | C8067: 1 | D8067: Mumbai | E8067: 8A, Janta Industrial Estate, Opposite Phoenix Mills, Senapati Bapat Road, Lower Parel, Mumbai | F8067: Lower Parel | G8067: Lower Parel, Mumbai | H8067: 72.825553 | I8067: 18.994237 | J8067: North Indian | K8067: Indian Rupees(Rs.) | L8067: No | M8067: Yes | N8067: No | O8067: No | P8067: 3 | Q8067: 3370 | R8067: 1500 | S8067: =IF(Table1[[#This Row],[Average_Cost_for_two]]<500,"Low",IF(Table1[[#This Row],[Average_Cost_for_two]]<=1500,"Medium","High")) -> Medium | T8067: 4.2 | U8067: 2011 | V8067: 10 | W8067: 18 | X8067: =IF(OR(Main!$U8067=0, Main!$V8067=0, Main!$W8067=0), "", DATE(Main!$U8067, Main!$V8067, Main!$W8067) ) -> 40834 | Y8067: =Table1[[#This Row],[Average_Cost_for_two]]*VLOOKUP(Table1[[#This Row],[Currency]],currency!$A$2:$B$10,2,FALSE) -> 18 | Z8067: =VLOOKUP(C8067,country!A:B,2,FALSE) -> India | AA8067: =ROUNDUP(V8067/3,0) -> 4
A8068: 3400073 | B8068: The Latitude - Radisson Blu | C8068: 1 | D8068: Agra | E8068: Radisson Blu, Taj East Gate Road, Tajganj, Agra | F8068: Radisson Blu, Tajganj | G8068: Radisson Blu, Tajganj, Agra | H8068: 78.057044 | I8068: 27.163303 | J8068: North Indian, Chinese, Continental | K8068: Indian Rupees(Rs.) | L8068: No | M8068: No | N8068: No | O8068: No | P8068: 1 | Q8068: 103 | S8068: =IF(Table1[[#This Row],[Average_Cost_for_two]]<500,"Low",IF(Table1[[#This Row],[Average_Cost_for_two]]<=1500,"Medium","High")) -> Low | T8068: 3.9 | U8068: 2013 | V8068: 9 | W8068: 23 | X8068: =IF(OR(Main!$U8068=0, Main!$V8068=0, Main!$W8068=0), "", DATE(Main!$U8068, Main!$V8068, Main!$W8068) ) -> 41540 | Y8068: =Table1[[#This Row],[Average_Cost_for_two]]*VLOOKUP(Table1[[#This Row],[Currency]],currency!$A$2:$B$10,2,FALSE) -> 0 | Z8068: =VLOOKUP(C8068,country!A:B,2,FALSE) -> India | AA8068: =ROUNDUP(V8068/3,0) -> 3
A8069: 56618 | B8069: AB's - Absolute Barbecues | C8069: 1 | D8069: Bangalore | E8069: 90/4, 3rd Floor, Outer Ring Road, Munnekollaly Village, Marathahalli, Bangalore | F8069: Marathahalli | G8069: Marathahalli, Bangalore | H8069: 77.699386 | I8069: 12.949934 | J8069: European, Mediterranean, North Indian | K8069: Indian Rupees(Rs.) | L8069: No | M8069: No | N8069: No | O8069: No | P8069: 3 | Q8069: 6907 | R8069: 1400 | S8069: =IF(Table1[[#This Row],[Average_Cost_for_two]]<500,"Low",IF(Table1[[#This Row],[Average_Cost_for_two]]<=1500,"Medium","High")) -> Medium | T8069: 4.6 | U8069: 2011 | V8069: 9 | W8069: 21 | X8069: =IF(OR(Main!$U8069=0, Main!$V8069=0, Main!$W8069=0), "", DATE(Main!$U8069, Main!$V8069, Main!$W8069) ) -> 40807 | Y8069: =Table1[[#This Row],[Average_Cost_for_two]]*VLOOKUP(Table1[[#This Row],[Currency]],currency!$A$2:$B$10,2,FALSE) -> 16.8 | Z8069: =VLOOKUP(C8069,country!A:B,2,FALSE) -> India | AA8069: =ROUNDUP(V8069/3,0) -> 3
A8070: 2600180 | B8070: Indian Coffee House | C8070: 1 | D8070: Bhopal | E8070: Near Apex Bank, TT Nagar, Bhopal | F8070: TT Nagar | G8070: TT Nagar, Bhopal | H8070: 77.401663 | I8070: 23.234631 | J8070: South Indian | K8070: Indian Rupees(Rs.) | L8070: No | M8070: No | N8070: No | O8070: No | P8070: 2 | Q8070: 161 | R8070: 500 | S8070: =IF(Table1[[#This Row],[Average_Cost_for_two]]<500,"Low",IF(Table1[[#This Row],[Average_Cost_for_two]]<=1500,"Medium","High")) -> Medium | T8070: 3.9 | U8070: 2016 | V8070: 9 | W8070: 8 | X8070: =IF(OR(Main!$U8070=0, Main!$V8070=0, Main!$W8070=0), "", DATE(Main!$U8070, Main!$V8070, Main!$W8070) ) -> 42621 | Y8070: =Table1[[#This Row],[Average_Cost_for_two]]*VLOOKUP(Table1[[#This Row],[Currency]],currency!$A$2:$B$10,2,FALSE) -> 6 | Z8070: =VLOOKUP(C8070,country!A:B,2,FALSE) -> India | AA8070: =ROUNDUP(V8070/3,0) -> 3
A8071: 2600007 | B8071: Bake N Shake | C8071: 1 | D8071: Bhopal | E8071: Bhadbhada Road, Near Rang Mahal Talkies, TT Nagar, Bhopal | F8071: TT Nagar | G8071: TT Nagar, Bhopal | H8071: 77.398886 | I8071: 23.235123 | J8071: Fast Food | K8071: Indian Rupees(Rs.) | L8071: No | M8071: No | N8071: No | O8071: No | P8071: 2 | Q8071: 120 | R8071: 500 | S8071: =IF(Table1[[#This Row],[Average_Cost_for_two]]<500,"Low",IF(Table1[[#This Row],[Average_Cost_for_two]]<=1500,"Medium","High")) -> Medium | T8071: 4.3 | U8071: 2011 | V8071: 9 | W8071: 8 | X8071: =IF(OR(Main!$U8071=0, Main!$V8071=0, Main!$W8071=0), "", DATE(Main!$U8071, Main!$V8071, Main!$W8071) ) -> 40794 | Y8071: =Table1[[#This Row],[Average_Cost_for_two]]*VLOOKUP(Table1[[#This Row],[Currency]],currency!$A$2:$B$10,2,FALSE) -> 6 | Z8071: =VLOOKUP(C8071,country!A:B,2,FALSE) -> India | AA8071: =ROUNDUP(V8071/3,0) -> 3
A8072: 2900020 | B8072: Lal Qila | C8072: 1 | D8072: Bhubaneshwar | E8072: Sampark Vihar, Opposite Big Bazaar, KIIT Square, Patia, Bhubaneshwar | F8072: Patia | G8072: Patia, Bhubaneshwar | H8072: 85.82685 | I8072: 20.352992 | J8072: Mughlai, Chinese, North Indian | K8072: Indian Rupees(Rs.) | L8072: No | M8072: No | N8072: No | O8072: No | P8072: 2 | Q8072: 228 | R8072: 500 | S8072: =IF(Table1[[#This Row],[Average_Cost_for_two]]<500,"Low",IF(Table1[[#This Row],[Average_Cost_for_two]]<=1500,"Medium","High")) -> Medium | T8072: 3.7 | U8072: 2010 | V8072: 9 | W8072: 17 | X8072: =IF(OR(Main!$U8072=0, Main!$V8072=0, Main!$W8072=0), "", DATE(Main!$U8072, Main!$V8072, Main!$W8072) ) -> 40438 | Y8072: =Table1[[#This Row],[Average_Cost_for_two]]*VLOOKUP(Table1[[#This Row],[Currency]],currency!$A$2:$B$10,2,FALSE) -> 6 | Z8072: =VLOOKUP(C8072,country!A:B,2,FALSE) -> India | AA8072: =ROUNDUP(V8072/3,0) -> 3
A8073: 121312 | B8073: Mocha | C8073: 1 | D8073: Chandigarh | E8073: Ground Floor, Elante Mall, Phase 1, Chandigarh Industrial Area, Chandigarh | F8073: Elante Mall, Chandigarh Industrial Area | G8073: Elante Mall, Chandigarh Industrial Area, Chandigarh | H8073: 76.800865 | I8073: 30.705148 | J8073: Continental, Italian, Thai, Finger Food | K8073: Indian Rupees(Rs.) | L8073: No | M8073: No | N8073: No | O8073: No | P8073: 3 | Q8073: 428 | R8073: 1400 | S8073: =IF(Table1[[#This Row],[Average_Cost_for_two]]<500,"Low",IF(Table1[[#This Row],[Average_Cost_for_two]]<=1500,"Medium","High")) -> Medium | T8073: 4 | U8073: 2010 | V8073: 9 | W8073: 1 | X8073: =IF(OR(Main!$U8073=0, Main!$V8073=0, Main!$W8073=0), "", DATE(Main!$U8073, Main!$V8073, Main!$W8073) ) -> 40422 | Y8073: =Table1[[#This Row],[Average_Cost_for_two]]*VLOOKUP(Table1[[#This Row],[Currency]],currency!$A$2:$B$10,2,FALSE) -> 16.8 | Z8073: =VLOOKUP(C8073,country!A:B,2,FALSE) -> India | AA8073: =ROUNDUP(V8073/3,0) -> 3
A8074: 123125 | B8074: TGI Friday's | C8074: 1 | D8074: Chandigarh | E8074: SCO 51, Madhya Marg, Sector 26, Chandigarh | F8074: Sector 26 | G8074: Sector 26, Chandigarh | H8074: 76.806363 | I8074: 30.724943 | J8074: American, Tex-Mex | K8074: Indian Rupees(Rs.) | L8074: No | M8074: No | N8074: No | O8074: No | P8074: 3 | Q8074: 228 | R8074: 1800 | S8074: =IF(Table1[[#This Row],[Average_Cost_for_two]]<500,"Low",IF(Table1[[#This Row],[Average_Cost_for_two]]<=1500,"Medium","High")) -> High | T8074: 4.3 | U8074: 2013 | V8074: 9 | W8074: 3 | X8074: =IF(OR(Main!$U8074=0, Main!$V8074=0, Main!$W8074=0), "", DATE(Main!$U8074, Main!$V8074, Main!$W8074) ) -> 41520 | Y8074: =Table1[[#This Row],[Average_Cost_for_two]]*VLOOKUP(Table1[[#This Row],[Currency]],currency!$A$2:$B$10,2,FALSE) -> 21.6 | Z8074: =VLOOKUP(C8074,country!A:B,2,FALSE) -> India | AA8074: =ROUNDUP(V8074/3,0) -> 3
A8075: 307580 | B8075: Side Wok | C8075: 1 | D8075: Gurgaon | E8075: Ground Floor, MPD Tower, Opposite Magnolias, DLF 5, Golf Course Road, Gurgaon | F8075: Golf Course Road | G8075: Golf Course Road, Gurgaon | H8075: 77.097185 | I8075: 28.454919 | J8075: Burmese, Chinese, Japanese, Malaysian, Thai | K8075: Indian Rupees(Rs.) | L8075: Yes | M8075: Yes | N8075: No | O8075: No | P8075: 4 | Q8075: 280 | R8075: 2000 | S8075: =IF(Table1[[#This Row],[Average_Cost_for_two]]<500,"Low",IF(Table1[[#This Row],[Average_Cost_for_two]]<=1500,"Medium","High")) -> High | T8075: 3.9 | U8075: 2017 | V8075: 8 | W8075: 7 | X8075: =IF(OR(Main!$U8075=0, Main!$V8075=0, Main!$W8075=0), "", DATE(Main!$U8075, Main!$V8075, Main!$W8075) ) -> 42954 | Y8075: =Table1[[#This Row],[Average_Cost_for_two]]*VLOOKUP(Table1[[#This Row],[Currency]],currency!$A$2:$B$10,2,FALSE) -> 24 | Z8075: =VLOOKUP(C8075,country!A:B,2,FALSE) -> India | AA8075: =ROUNDUP(V8075/3,0) -> 3
A8076: 7518 | B8076: Spiritual Bar & Lounge-DoubleTree by Hilton | C8076: 1 | D8076: Gurgaon | E8076: DoubleTree by Hilton, Golf Course Road, Sector 56, Gurgaon | F8076: DoubleTree by Hilton, Sector 56 | G8076: DoubleTree by Hilton, Sector 56, Gurgaon | H8076: 77.104693 | I8076: 28.422147 | J8076: Pizza, Italian | K8076: Indian Rupees(Rs.) | L8076: Yes | M8076: No | N8076: No | O8076: No | P8076: 4 | Q8076: 52 | R8076: 2000 | S8076: =IF(Table1[[#This Row],[Average_Cost_for_two]]<500,"Low",IF(Table1[[#This Row],[Average_Cost_for_two]]<=1500,"Medium","High")) -> High | T8076: 3.4 | U8076: 2010 | V8076: 6 | W8076: 16 | X8076: =IF(OR(Main!$U8076=0, Main!$V8076=0, Main!$W8076=0), "", DATE(Main!$U8076, Main!$V8076, Main!$W8076) ) -> 40345 | Y8076: =Table1[[#This Row],[Average_Cost_for_two]]*VLOOKUP(Table1[[#This Row],[Currency]],currency!$A$2:$B$10,2,FALSE) -> 24 | Z8076: =VLOOKUP(C8076,country!A:B,2,FALSE) -> India | AA8076: =ROUNDUP(V8076/3,0) -> 2
A8077: 18446415 | B8077: The Old School Brew House | C8077: 1 | D8077: Gurgaon | E8077: SCO 56, 4th Floor, Sector 29, Gurgaon | F8077: Sector 29 | G8077: Sector 29, Gurgaon | H8077: 77.064195 | I8077: 28.467777 | J8077: Continental, Burger, Pizza, North Indian, European, Finger Food | K8077: Indian Rupees(Rs.) | L8077: Yes | M8077: No | N8077: No | O8077: No | P8077: 4 | Q8077: 96 | R8077: 2000 | S8077: =IF(Table1[[#This Row],[Average_Cost_for_two]]<500,"Low",IF(Table1[[#This Row],[Average_Cost_for_two]]<=1500,"Medium","High")) -> High | T8077: 3.9 | U8077: 2011 | V8077: 6 | W8077: 1 | X8077: =IF(OR(Main!$U8077=0, Main!$V8077=0, Main!$W8077=0), "", DATE(Main!$U8077, Main!$V8077, Main!$W8077) ) -> 40695 | Y8077: =Table1[[#This Row],[Average_Cost_for_two]]*VLOOKUP(Table1[[#This Row],[Currency]],currency!$A$2:$B$10,2,FALSE) -> 24 | Z8077: =VLOOKUP(C8077,country!A:B,2,FALSE) -> India | AA8077: =ROUNDUP(V8077/3,0) -> 2
A8078: 306134 | B8078: The Wine Company | C8078: 1 | D8078: Gurgaon | E8078: Cyber Hub, DLF Cyber City, Gurgaon | F8078: Cyber Hub, DLF Cyber City | G8078: Cyber Hub, DLF Cyber City, Gurgaon | H8078: 77.089048 | I8078: 28.496229 | J8078: Italian, European | K8078: Indian Rupees(Rs.) | L8078: Yes | M8078: No | N8078: No | O8078: No | P8078: 4 | Q8078: 2412 | R8078: 2000 | S8078: =IF(Table1[[#This Row],[Average_Cost_for_two]]<500,"Low",IF(Table1[[#This Row],[Average_Cost_for_two]]<=1500,"Medium","High")) -> High | T8078: 2.4 | U8078: 2016 | V8078: 5 | W8078: 23 | X8078: =IF(OR(Main!$U8078=0, Main!$V8078=0, Main!$W8078=0), "", DATE(Main!$U8078, Main!$V8078, Main!$W8078) ) -> 42513 | Y8078: =Table1[[#This Row],[Average_Cost_for_two]]*VLOOKUP(Table1[[#This Row],[Currency]],currency!$A$2:$B$10,2,FALSE) -> 24 | Z8078: =VLOOKUP(C8078,country!A:B,2,FALSE) -> India | AA8078: =ROUNDUP(V8078/3,0) -> 2
A8079: 1401934 | B8079: Mama Loca | C8079: 1 | D8079: Indore | E8079: G-1, Princess Centre, 6/3, New Palasia, Indore | F8079: New Palasia | G8079: New Palasia, Indore | H8079: 75.884212 | I8079: 22.728163 | J8079: Greek, Lebanese | K8079: Indian Rupees(Rs.) | L8079: No | M8079: No | N8079: No | O8079: No | P8079: 3 | Q8079: 304 | R8079: 1000 | S8079: =IF(Table1[[#This Row],[Average_Cost_for_two]]<500,"Low",IF(Table1[[#This Row],[Average_Cost_for_two]]<=1500,"Medium","High")) -> Medium | T8079: 4.2 | U8079: 2016 | V8079: 9 | W8079: 25 | X8079: =IF(OR(Main!$U8079=0, Main!$V8079=0, Main!$W8079=0), "", DATE(Main!$U8079, Main!$V8079, Main!$W8079) ) -> 42638 | Y8079: =Table1[[#This Row],[Average_Cost_for_two]]*VLOOKUP(Table1[[#This Row],[Currency]],currency!$A$2:$B$10,2,FALSE) -> 12 | Z8079: =VLOOKUP(C8079,country!A:B,2,FALSE) -> India | AA8079: =ROUNDUP(V8079/3,0) -> 3
A8080: 18395137 | B8080: Just My Bakes | C8080: 1 | D8080: Indore | E8080: 5-B/F, Scheme 74C, Vijay Nagar, Indore | F8080: Vijay Nagar | G8080: Vijay Nagar, Indore | H8080: 75.892574 | I8080: 22.760072 | J8080: Cafe, Bakery | K8080: Indian Rupees(Rs.) | L8080: No | M8080: No | N8080: No | O8080: No | P8080: 2 | Q8080: 69 | R8080: 500 | S8080: =IF(Table1[[#This Row],[Average_Cost_for_two]]<500,"Low",IF(Table1[[#This Row],[Average_Cost_for_two]]<=1500,"Medium","High")) -> Medium | T8080: 3.9 | U8080: 2010 | V8080: 9 | W8080: 14 | X8080: =IF(OR(Main!$U8080=0, Main!$V8080=0, Main!$W8080=0), "", DATE(Main!$U8080, Main!$V8080, Main!$W8080) ) -> 40435 | Y8080: =Table1[[#This Row],[Average_Cost_for_two]]*VLOOKUP(Table1[[#This Row],[Currency]],currency!$A$2:$B$10,2,FALSE) -> 6 | Z8080: =VLOOKUP(C8080,country!A:B,2,FALSE) -> India | AA8080: =ROUNDUP(V8080/3,0) -> 3
... A8084: 2300483 | B8084: The Zaffran | C8084: 1 | D8084: Kanpur | E8084: Ratan Zone, Coca-Cola Crossing, Ashok Nagar, Kanpur | F8084: Ashok Nagar | G8084: Ashok Nagar, Kanpur | H8084: 80.313564 | I8084: 26.471617 | J8084: North Indian, Continental, Asian | K8084: Indian Rupees(Rs.) | L8084: No | M8084: No | N8084: No | O8084: No | P8084: 3 | Q8084: 51 | R8084: 800 | S8084: =IF(Table1[[#This Row],[Average_Cost_for_two]]<500,"Low",IF(Table1[[#This Row],[Average_Cost_for_two]]<=1500,"Medium","High")) -> Medium | T8084: 3.3 | U8084: 2014 | V8084: 9 | W8084: 23 | X8084: =IF(OR(Main!$U8084=0, Main!$V8084=0, Main!$W8084=0), "", DATE(Main!$U8084, Main!$V8084, Main!$W8084) ) -> 41905 | Y8084: =Table1[[#This Row],[Average_Cost_for_two]]*VLOOKUP(Table1[[#This Row],[Currency]],currency!$A$2:$B$10,2,FALSE) -> 9.6 | Z8084: =VLOOKUP(C8084,country!A:B,2,FALSE) -> India | AA8084: =ROUNDUP(V8084/3,0) -> 3
A8085: 18312106 | B8085: UrbanCrave | C8085: 1 | D8085: Kanpur | E8085: 14/125, The Mall, Mall Road, Colonelganj, Parade, Kanpur | F8085: Parade | G8085: Parade, Kanpur | H8085: 80.342796 | I8085: 26.474986 | J8085: Cafe, Continental, Desserts, Ice Cream, Italian, Beverages | K8085: Indian Rupees(Rs.) | L8085: No | M8085: No | N8085: No | O8085: No | P8085: 1 | Q8085: 127 | S8085: =IF(Table1[[#This Row],[Average_Cost_for_two]]<500,"Low",IF(Table1[[#This Row],[Average_Cost_for_two]]<=1500,"Medium","High")) -> Low | T8085: 3.9 | U8085: 2014 | V8085: 9 | W8085: 19 | X8085: =IF(OR(Main!$U8085=0, Main!$V8085=0, Main!$W8085=0), "", DATE(Main!$U8085, Main!$V8085, Main!$W8085) ) -> 41901 | Y8085: =Table1[[#This Row],[Average_Cost_for_two]]*VLOOKUP(Table1[[#This Row],[Currency]],currency!$A$2:$B$10,2,FALSE) -> 0 | Z8085: =VLOOKUP(C8085,country!A:B,2,FALSE) -> India | AA8085: =ROUNDUP(V8085/3,0) -> 3
A8086: 900800 | B8086: ChaiCofi | C8086: 1 | D8086: Kochi | E8086: Arammal Tower, Near Express Garden, KK Road, Kaloor, Kochi | F8086: Kaloor | G8086: Kaloor, Kochi | H8086: 76.293136 | I8086: 9.9917028 | J8086: Cafe, Continental, Italian | K8086: Indian Rupees(Rs.) | L8086: No | M8086: No | N8086: No | O8086: No | P8086: 2 | Q8086: 160 | R8086: 800 | S8086: =IF(Table1[[#This Row],[Average_Cost_for_two]]<500,"Low",IF(Table1[[#This Row],[Average_Cost_for_two]]<=1500,"Medium","High")) -> Medium | T8086: 4 | U8086: 2010 | V8086: 9 | W8086: 7 | X8086: =IF(OR(Main!$U8086=0, Main!$V8086=0, Main!$W8086=0), "", DATE(Main!$U8086, Main!$V8086, Main!$W8086) ) -> 40428 | Y8086: =Table1[[#This Row],[Average_Cost_for_two]]*VLOOKUP(Table1[[#This Row],[Currency]],currency!$A$2:$B$10,2,FALSE) -> 9.6 | Z8086: =VLOOKUP(C8086,country!A:B,2,FALSE) -> India | AA8086: =ROUNDUP(V8086/3,0) -> 3
A8087: 800468 | B8087: Grandson of Tunday Kababi | C8087: 1 | D8087: Lucknow | E8087: Naaz Cinema Road, Aminabad, Lucknow | F8087: Aminabad | G8087: Aminabad, Lucknow | H8087: 80.927431 | I8087: 26.848506 | J8087: Mughlai, Lucknowi | K8087: Indian Rupees(Rs.) | L8087: No | M8087: No | N8087: No | O8087: No | P8087: 1 | Q8087: 1057 | R8087: 300 | S8087: =IF(Table1[[#This Row],[Average_Cost_for_two]]<500,"Low",IF(Table1[[#This Row],[Average_Cost_for_two]]<=1500,"Medium","High")) -> Low | T8087: 4.9 | U8087: 2013 | V8087: 9 | W8087: 20 | X8087: =IF(OR(Main!$U8087=0, Main!$V8087=0, Main!$W8087=0), "", DATE(Main!$U8087, Main!$V8087, Main!$W8087) ) -> 41537 | Y8087: =Table1[[#This Row],[Average_Cost_for_two]]*VLOOKUP(Table1[[#This Row],[Currency]],currency!$A$2:$B$10,2,FALSE) -> 3.6 | Z8087: =VLOOKUP(C8087,country!A:B,2,FALSE) -> India | AA8087: =ROUNDUP(V8087/3,0) -> 3
A8088: 18375866 | B8088: Free Spirit | C8088: 1 | D8088: Lucknow | E8088: Indira Gandhi Pratishthan-Kathauta Chauraha road, Near Shaheed Path Flyover, Vishesh Khand 2, Gomti Nagar, Lucknow | F8088: Gomti Nagar | G8088: Gomti Nagar, Lucknow | H8088: 81.015159 | I8088: 26.867445 | J8088: Cafe, Italian | K8088: Indian Rupees(Rs.) | L8088: No | M8088: No | N8088: No | O8088: No | P8088: 2 | Q8088: 106 | R8088: 450 | S8088: =IF(Table1[[#This Row],[Average_Cost_for_two]]<500,"Low",IF(Table1[[#This Row],[Average_Cost_for_two]]<=1500,"Medium","High")) -> Low | T8088: 4.3 | U8088: 2014 | V8088: 9 | W8088: 28 | X8088: =IF(OR(Main!$U8088=0, Main!$V8088=0, Main!$W8088=0), "", DATE(Main!$U8088, Main!$V8088, Main!$W8088) ) -> 41910 | Y8088: =Table1[[#This Row],[Average_Cost_for_two]]*VLOOKUP(Table1[[#This Row],[Currency]],currency!$A$2:$B$10,2,FALSE) -> 5.4 | Z8088: =VLOOKUP(C8088,country!A:B,2,FALSE) -> India | AA8088: =ROUNDUP(V8088/3,0) -> 3
A8089: 3100010 | B8089: Diesel Cafe | C8089: 1 | D8089: Mangalore | E8089: Ground Floor, Hotel Prestige, Near Collector's Gate, Balmatta, Mangalore | F8089: Balmatta | G8089: Balmatta, Mangalore | H8089: 74.852744 | I8089: 12.873678 | J8089: American, Italian | K8089: Indian Rupees(Rs.) | L8089: No | M8089: No | N8089: No | O8089: No | P8089: 3 | Q8089: 196 | R8089: 900 | S8089: =IF(Table1[[#This Row],[Average_Cost_for_two]]<500,"Low",IF(Table1[[#This Row],[Average_Cost_for_two]]<=1500,"Medium","High")) -> Medium | T8089: 3.8 | U8089: 2013 | V8089: 9 | W8089: 19 | X8089: =IF(OR(Main!$U8089=0, Main!$V8089=0, Main!$W8089=0), "", DATE(Main!$U8089, Main!$V8089, Main!$W8089) ) -> 41536 | Y8089: =Table1[[#This Row],[Average_Cost_for_two]]*VLOOKUP(Table1[[#This Row],[Currency]],currency!$A$2:$B$10,2,FALSE) -> 10.8 | Z8089: =VLOOKUP(C8089,country!A:B,2,FALSE) -> India | AA8089: =ROUNDUP(V8089/3,0) -> 3
A8090: 3100145 | B8090: Froth On Top | C8090: 1 | D8090: Mangalore | E8090: Silk House, Balmatta Arya Samaj Road, Balmatta, Mangalore | F8090: Balmatta | G8090: Balmatta, Mangalore | H8090: 74.851586 | I8090: 12.873531 | J8090: Chinese, Mangalorean | K8090: Indian Rupees(Rs.) | L8090: No | M8090: No | N8090: No | O8090: No | P8090: 2 | Q8090: 355 | R8090: 700 | S8090: =IF(Table1[[#This Row],[Average_Cost_for_two]]<500,"Low",IF(Table1[[#This Row],[Average_Cost_for_two]]<=1500,"Medium","High")) -> Medium | T8090: 3.7 | U8090: 2016 | V8090: 9 | W8090: 19 | X8090: =IF(OR(Main!$U8090=0, Main!$V8090=0, Main!$W8090=0), "", DATE(Main!$U8090, Main!$V8090, Main!$W8090) ) -> 42632 | Y8090: =Table1[[#This Row],[Average_Cost_for_two]]*VLOOKUP(Table1[[#This Row],[Currency]],currency!$A$2:$B$10,2,FALSE) -> 8.4 | Z8090: =VLOOKUP(C8090,country!A:B,2,FALSE) -> India | AA8090: =ROUNDUP(V8090/3,0) -> 3
A8091: 18233317 | B8091: 145 Kala Ghoda | C8091: 1 | D8091: Mumbai | E8091: 145, Kala Ghoda, Fort, Mumbai | F8091: Fort | G8091: Fort, Mumbai | H8091: 72.832585 | I8091: 18.927584 | J8091: Fast Food, Beverages, Desserts | K8091: Indian Rupees(Rs.) | L8091: No | M8091: No | N8091: No | O8091: No | P8091: 3 | Q8091: 1606 | R8091: 1500 | S8091: =IF(Table1[[#This Row],[Average_Cost_for_two]]<500,"Low",IF(Table1[[#This Row],[Average_Cost_for_two]]<=1500,"Medium","High")) -> Medium | T8091: 4.2 | U8091: 2012 | V8091: 9 | W8091: 5 | X8091: =IF(OR(Main!$U8091=0, Main!$V8091=0, Main!$W8091=0), "", DATE(Main!$U8091, Main!$V8091, Main!$W8091) ) -> 41157 | Y8091: =Table1[[#This Row],[Average_Cost_for_two]]*VLOOKUP(Table1[[#This Row],[Currency]],currency!$A$2:$B$10,2,FALSE) -> 18 | Z8091: =VLOOKUP(C8091,country!A:B,2,FALSE) -> India | AA8091: =ROUNDUP(V8091/3,0) -> 3
A8092: 3600265 | B8092: Jalpaan Dining Saga | C8092: 1 | D8092: Mysore | E8092: 366, 2nd & 3rd Floor, Near Ramaswamy Circle, Chamaraja Mohalla, Chamrajpura, Mysore | F8092: Chamrajpura | G8092: Chamrajpura, Mysore | H8092: 76.643622 | I8092: 12.304569 | J8092: North Indian, Chinese, Italian | K8092: Indian Rupees(Rs.) | L8092: No | M8092: No | N8092: No | O8092: No | P8092: 3 | Q8092: 172 | R8092: 900 | S8092: =IF(Table1[[#This Row],[Average_Cost_for_two]]<500,"Low",IF(Table1[[#This Row],[Average_Cost_for_two]]<=1500,"Medium","High")) -> Medium | T8092: 3.7 | U8092: 2016 | V8092: 9 | W8092: 8 | X8092: =IF(OR(Main!$U8092=0, Main!$V8092=0, Main!$W8092=0), "", DATE(Main!$U8092, Main!$V8092, Main!$W8092) ) -> 42621 | Y8092: =Table1[[#This Row],[Average_Cost_for_two]]*VLOOKUP(Table1[[#This Row],[Currency]],currency!$A$2:$B$10,2,FALSE) -> 10.8 | Z8092: =VLOOKUP(C8092,country!A:B,2,FALSE) -> India | AA8092: =ROUNDUP(V8092/3,0) -> 3
A8093: 18441771 | B8093: The Ark | C8093: 1 | D8093: Gurgaon | E8093: Address One, Second Floor, Next to Hilton Double Tree Hotel, Baani, Sector 56, Golf Course Road, Gurgaon | F8093: Golf Course Road | G8093: Golf Course Road, Gurgaon | H8093: 77.105038 | I8093: 28.421812 | J8093: Seafood, Mediterranean | K8093: Indian Rupees(Rs.) | L8093: Yes | M8093: No | N8093: No | O8093: No | P8093: 4 | Q8093: 45 | R8093: 2000 | S8093: =IF(Table1[[#This Row],[Average_Cost_for_two]]<500,"Low",IF(Table1[[#This Row],[Average_Cost_for_two]]<=1500,"Medium","High")) -> High | T8093: 3.7 | U8093: 2017 | V8093: 5 | W8093: 24 | X8093: =IF(OR(Main!$U8093=0, Main!$V8093=0, Main!$W8093=0), "", DATE(Main!$U8093, Main!$V8093, Main!$W8093) ) -> 42879 | Y8093: =Table1[[#This Row],[Average_Cost_for_two]]*VLOOKUP(Table1[[#This Row],[Currency]],currency!$A$2:$B$10,2,FALSE) -> 24 | Z8093: =VLOOKUP(C8093,country!A:B,2,FALSE) -> India | AA8093: =ROUNDUP(V8093/3,0) -> 2
A8094: 3600361 | B8094: Tandooriwala | C8094: 1 | D8094: Mysore | E8094: 26, 1st Stage, KHB, Nrupathunga Road, Kuvempunagar, Mysore | F8094: Kuvempunagar | G8094: Kuvempunagar, Mysore | H8094: 76.625861 | I8094: 12.284747 | J8094: North Indian | K8094: Indian Rupees(Rs.) | L8094: No | M8094: No | N8094: No | O8094: No | P8094: 2 | Q8094: 127 | R8094: 700 | S8094: =IF(Table1[[#This Row],[Average_Cost_for_two]]<500,"Low",IF(Table1[[#This Row],[Average_Cost_for_two]]<=1500,"Medium","High")) -> Medium | T8094: 3.5 | U8094: 2014 | V8094: 9 | W8094: 8 | X8094: =IF(OR(Main!$U8094=0, Main!$V8094=0, Main!$W8094=0), "", DATE(Main!$U8094, Main!$V8094, Main!$W8094) ) -> 41890 | Y8094: =Table1[[#This Row],[Average_Cost_for_two]]*VLOOKUP(Table1[[#This Row],[Currency]],currency!$A$2:$B$10,2,FALSE) -> 8.4 | Z8094: =VLOOKUP(C8094,country!A:B,2,FALSE) -> India | AA8094: =ROUNDUP(V8094/3,0) -> 3
A8095: 3600072 | B8095: Nanking | C8095: 1 | D8095: Mysore | E8095: High Tension Double Road, Near Vidyavardhaka College, 2nd Stage, Vijay Nagar, Mysore | F8095: Vijay Nagar | G8095: Vijay Nagar, Mysore | H8095: 76.617889 | I8095: 12.337928 | J8095: Chinese, Thai | K8095: Indian Rupees(Rs.) | L8095: No | M8095: No | N8095: No | O8095: No | P8095: 2 | Q8095: 208 | R8095: 550 | S8095: =IF(Table1[[#This Row],[Average_Cost_for_two]]<500,"Low",IF(Table1[[#This Row],[Average_Cost_for_two]]<=1500,"Medium","High")) -> Medium | T8095: 3.7 | U8095: 2011 | V8095: 9 | W8095: 16 | X8095: =IF(OR(Main!$U8095=0, Main!$V8095=0, Main!$W8095=0), "", DATE(Main!$U8095, Main!$V8095, Main!$W8095) ) -> 40802 | Y8095: =Table1[[#This Row],[Average_Cost_for_two]]*VLOOKUP(Table1[[#This Row],[Currency]],currency!$A$2:$B$10,2,FALSE) -> 6.6 | Z8095: =VLOOKUP(C8095,country!A:B,2,FALSE) -> India | AA8095: =ROUNDUP(V8095/3,0) -> 3
A8096: 1600067 | B8096: Al Arabian Express | C8096: 1 | D8096: Nashik | E8096: Near Big Bazar, College Road, Nashik | F8096: College Road | G8096: College Road, Nashik | H8096: 73.765043 | I8096: 20.003734 | J8096: Mughlai | K8096: Indian Rupees(Rs.) | L8096: No | M8096: No | N8096: No | O8096: No | P8096: 3 | Q8096: 162 | R8096: 500 | S8096: =IF(Table1[[#This Row],[Average_Cost_for_two]]<500,"Low",IF(Table1[[#This Row],[Average_Cost_for_two]]<=1500,"Medium","High")) -> Medium | T8096: 3.7 | U8096: 2018 | V8096: 9 | W8096: 21 | X8096: =IF(OR(Main!$U8096=0, Main!$V8096=0, Main!$W8096=0), "", DATE(Main!$U8096, Main!$V8096, Main!$W8096) ) -> 43364 | Y8096: =Table1[[#This Row],[Average_Cost_for_two]]*VLOOKUP(Table1[[#This Row],[Currency]],currency!$A$2:$B$10,2,FALSE) -> 6 | Z8096: =VLOOKUP(C8096,country!A:B,2,FALSE) -> India | AA8096: =ROUNDUP(V8096/3,0) -> 3
...

Sheet country
A1: CountryID | B1: Countryname
A2: 1 | B2: India
A3: 14 | B3: Australia
A4: 30 | B4: Brazil
A5: 37 | B5: Canada
A6: 94 | B6: Indonasia
A7: 148 | B7: New Zealand
A8: 162 | B8: Phillipines
A9: 166 | B9: Qatar
A10: 184 | B10: Singapore
A11: 189 | B11: South Africa
A12: 191 | B12: Sri lanka
A13: 208 | B13: Turkey
... A16: 216 | B16: United States

Sheet currency
A1: Currency | B1: USD Rate
A2: Indian Rupees(Rs.) | B2: 0.012
A3: Dollar($) | B3: 1
A4: Pounds(Œ£) | B4: 1.24
A5: NewZealand($) | B5: 0.6
A6: Emirati Diram(AED) | B6: 0.27
A7: Brazilian Real(R$) | B7: 0.2
A8: Turkish Lira(TL) | B8: 0.05
A9: Qatari Rial(QR) | B9: 0.27
A10: Rand(R) | B10: 0.051
A11: Botswana Pula(P) | B11: 0.073
A12: Sri Lankan Rupee(LKR) | B12: 0.0034
A13: Indonesian Rupiah(IDR) | B13: 6.7e-05

Sheet Date
A1: DateKey | B1: Year | C1: Monthno | D1: Monthfullname | E1: Quarter | F1: YearMonth | G1: Weekdayno | H1: Weekdayname | I1: FinancialMonth | J1: Financial Quarter | N1: Min date | O1: =MIN(Main!$X$1:$X$9553) -> 40179
A2: =IF($O$1+ROW(A1)-1<=$O$3,$O$1+ROW(A1)-1,"") -> 40179 | B2: =YEAR(A2) -> 2010 | C2: =MONTH(A2) -> 1 | D2: =TEXT(A2,"mmmm") -> January | E2: ="Q"&ROUNDUP(MONTH(A2)/3,0) -> Q1 | F2: =TEXT(A2,"yyyy-mmm") -> 2010-Jan | G2: =WEEKDAY(A2,2) -> 5 | H2: =TEXT(A2,"dddd") -> Friday | I2: ="FM"&MOD(MONTH(A2)-4,12)+1 -> FM10 | J2: ="FQ-" & INT((MOD(MONTH(A2)-4,12)/3)+1) -> FQ-4
A3: =IF($O$1+ROW(A2)-1<=$O$3,$O$1+ROW(A2)-1,"") -> 40180 | B3: =YEAR(A3) -> 2010 | C3: =MONTH(A3) -> 1 | D3: =TEXT(A3,"mmmm") -> January | E3: ="Q"&ROUNDUP(MONTH(A3)/3,0) -> Q1 | F3: =TEXT(A3,"yyyy-mmm") -> 2010-Jan | G3: =WEEKDAY(A3,2) -> 6 | H3: =TEXT(A3,"dddd") -> Saturday | I3: ="FM"&MOD(MONTH(A3)-4,12)+1 -> FM10 | J3: ="FQ-" & INT((MOD(MONTH(A3)-4,12)/3)+1) -> FQ-4 | N3: Max date | O3: =MAX(Main!$X$2:$X$9552) -> 43462
A4: =IF($O$1+ROW(A3)-1<=$O$3,$O$1+ROW(A3)-1,"") -> 40181 | B4: =YEAR(A4) -> 2010 | C4: =MONTH(A4) -> 1 | D4: =TEXT(A4,"mmmm") -> January | E4: ="Q"&ROUNDUP(MONTH(A4)/3,0) -> Q1 | F4: =TEXT(A4,"yyyy-mmm") -> 2010-Jan | G4: =WEEKDAY(A4,2) -> 7 | H4: =TEXT(A4,"dddd") -> Sunday | I4: ="FM"&MOD(MONTH(A4)-4,12)+1 -> FM10 | J4: ="FQ-" & INT((MOD(MONTH(A4)-4,12)/3)+1) -> FQ-4
A5: =IF($O$1+ROW(A4)-1<=$O$3,$O$1+ROW(A4)-1,"") -> 40182 | B5: =YEAR(A5) -> 2010 | C5: =MONTH(A5) -> 1 | D5: =TEXT(A5,"mmmm") -> January | E5: ="Q"&ROUNDUP(MONTH(A5)/3,0) -> Q1 | F5: =TEXT(A5,"yyyy-mmm") -> 2010-Jan | G5: =WEEKDAY(A5,2) -> 1 | H5: =TEXT(A5,"dddd") -> Monday | I5: ="FM"&MOD(MONTH(A5)-4,12)+1 -> FM10 | J5: ="FQ-" & INT((MOD(MONTH(A5)-4,12)/3)+1) -> FQ-4
A6: =IF($O$1+ROW(A5)-1<=$O$3,$O$1+ROW(A5)-1,"") -> 40183 | B6: =YEAR(A6) -> 2010 | C6: =MONTH(A6) -> 1 | D6: =TEXT(A6,"mmmm") -> January | E6: ="Q"&ROUNDUP(MONTH(A6)/3,0) -> Q1 | F6: =TEXT(A6,"yyyy-mmm") -> 2010-Jan | G6: =WEEKDAY(A6,2) -> 2 | H6: =TEXT(A6,"dddd") -> Tuesday | I6: ="FM"&MOD(MONTH(A6)-4,12)+1 -> FM10 | J6: ="FQ-" & INT((MOD(MONTH(A6)-4,12)/3)+1) -> FQ-4
A7: =IF($O$1+ROW(A6)-1<=$O$3,$O$1+ROW(A6)-1,"") -> 40184 | B7: =YEAR(A7) -> 2010 | C7: =MONTH(A7) -> 1 | D7: =TEXT(A7,"mmmm") -> January | E7: ="Q"&ROUNDUP(MONTH(A7)/3,0) -> Q1 | F7: =TEXT(A7,"yyyy-mmm") -> 2010-Jan | G7: =WEEKDAY(A7,2) -> 3 | H7: =TEXT(A7,"dddd") -> Wednesday | I7: ="FM"&MOD(MONTH(A7)-4,12)+1 -> FM10 | J7: ="FQ-" & INT((MOD(MONTH(A7)-4,12)/3)+1) -> FQ-4
A8: =IF($O$1+ROW(A7)-1<=$O$3,$O$1+ROW(A7)-1,"") -> 40185 | B8: =YEAR(A8) -> 2010 | C8: =MONTH(A8) -> 1 | D8: =TEXT(A8,"mmmm") -> January | E8: ="Q"&ROUNDUP(MONTH(A8)/3,0) -> Q1 | F8: =TEXT(A8,"yyyy-mmm") -> 2010-Jan | G8: =WEEKDAY(A8,2) -> 4 | H8: =TEXT(A8,"dddd") -> Thursday | I8: ="FM"&MOD(MONTH(A8)-4,12)+1 -> FM10 | J8: ="FQ-" & INT((MOD(MONTH(A8)-4,12)/3)+1) -> FQ-4
A9: =IF($O$1+ROW(A8)-1<=$O$3,$O$1+ROW(A8)-1,"") -> 40186 | B9: =YEAR(A9) -> 2010 | C9: =MONTH(A9) -> 1 | D9: =TEXT(A9,"mmmm") -> January | E9: ="Q"&ROUNDUP(MONTH(A9)/3,0) -> Q1 | F9: =TEXT(A9,"yyyy-mmm") -> 2010-Jan | G9: =WEEKDAY(A9,2) -> 5 | H9: =TEXT(A9,"dddd") -> Friday | I9: ="FM"&MOD(MONTH(A9)-4,12)+1 -> FM10 | J9: ="FQ-" & INT((MOD(MONTH(A9)-4,12)/3)+1) -> FQ-4
A10: =IF($O$1+ROW(A9)-1<=$O$3,$O$1+ROW(A9)-1,"") -> 40187 | B10: =YEAR(A10) -> 2010 | C10: =MONTH(A10) -> 1 | D10: =TEXT(A10,"mmmm") -> January | E10: ="Q"&ROUNDUP(MONTH(A10)/3,0) -> Q1 | F10: =TEXT(A10,"yyyy-mmm") -> 2010-Jan | G10: =WEEKDAY(A10,2) -> 6 | H10: =TEXT(A10,"dddd") -> Saturday | I10: ="FM"&MOD(MONTH(A10)-4,12)+1 -> FM10 | J10: ="FQ-" & INT((MOD(MONTH(A10)-4,12)/3)+1) -> FQ-4
A11: =IF($O$1+ROW(A10)-1<=$O$3,$O$1+ROW(A10)-1,"") -> 40188 | B11: =YEAR(A11) -> 2010 | C11: =MONTH(A11) -> 1 | D11: =TEXT(A11,"mmmm") -> January | E11: ="Q"&ROUNDUP(MONTH(A11)/3,0) -> Q1 | F11: =TEXT(A11,"yyyy-mmm") -> 2010-Jan | G11: =WEEKDAY(A11,2) -> 7 | H11: =TEXT(A11,"dddd") -> Sunday | I11: ="FM"&MOD(MONTH(A11)-4,12)+1 -> FM10 | J11: ="FQ-" & INT((MOD(MONTH(A11)-4,12)/3)+1) -> FQ-4
A12: =IF($O$1+ROW(A11)-1<=$O$3,$O$1+ROW(A11)-1,"") -> 40189 | B12: =YEAR(A12) -> 2010 | C12: =MONTH(A12) -> 1 | D12: =TEXT(A12,"mmmm") -> January | E12: ="Q"&ROUNDUP(MONTH(A12)/3,0) -> Q1 | F12: =TEXT(A12,"yyyy-mmm") -> 2010-Jan | G12: =WEEKDAY(A12,2) -> 1 | H12: =TEXT(A12,"dddd") -> Monday | I12: ="FM"&MOD(MONTH(A12)-4,12)+1 -> FM10 | J12: ="FQ-" & INT((MOD(MONTH(A12)-4,12)/3)+1) -> FQ-4
A13: =IF($O$1+ROW(A12)-1<=$O$3,$O$1+ROW(A12)-1,"") -> 40190 | B13: =YEAR(A13) -> 2010 | C13: =MONTH(A13) -> 1 | D13: =TEXT(A13,"mmmm") -> January | E13: ="Q"&ROUNDUP(MONTH(A13)/3,0) -> Q1 | F13: =TEXT(A13,"yyyy-mmm") -> 2010-Jan | G13: =WEEKDAY(A13,2) -> 2 | H13: =TEXT(A13,"dddd") -> Tuesday | I13: ="FM"&MOD(MONTH(A13)-4,12)+1 -> FM10 | J13: ="FQ-" & INT((MOD(MONTH(A13)-4,12)/3)+1) -> FQ-4
A14: =IF($O$1+ROW(A13)-1<=$O$3,$O$1+ROW(A13)-1,"") -> 40191 | B14: =YEAR(A14) -> 2010 | C14: =MONTH(A14) -> 1 | D14: =TEXT(A14,"mmmm") -> January | E14: ="Q"&ROUNDUP(MONTH(A14)/3,0) -> Q1 | F14: =TEXT(A14,"yyyy-mmm") -> 2010-Jan | G14: =WEEKDAY(A14,2) -> 3 | H14: =TEXT(A14,"dddd") -> Wednesday | I14: ="FM"&MOD(MONTH(A14)-4,12)+1 -> FM10 | J14: ="FQ-" & INT((MOD(MONTH(A14)-4,12)/3)+1) -> FQ-4
A15: =IF($O$1+ROW(A14)-1<=$O$3,$O$1+ROW(A14)-1,"") -> 40192 | B15: =YEAR(A15) -> 2010 | C15: =MONTH(A15) -> 1 | D15: =TEXT(A15,"mmmm") -> January | E15: ="Q"&ROUNDUP(MONTH(A15)/3,0) -> Q1 | F15: =TEXT(A15,"yyyy-mmm") -> 2010-Jan | G15: =WEEKDAY(A15,2) -> 4 | H15: =TEXT(A15,"dddd") -> Thursday | I15: ="FM"&MOD(MONTH(A15)-4,12)+1 -> FM10 | J15: ="FQ-" & INT((MOD(MONTH(A15)-4,12)/3)+1) -> FQ-4
... A3285: =IF($O$1+ROW(A3284)-1<=$O$3,$O$1+ROW(A3284)-1,"") -> 43462 | B3285: =YEAR(A3285) -> 2018 | C3285: =MONTH(A3285) -> 12 | D3285: =TEXT(A3285,"mmmm") -> December | E3285: ="Q"&ROUNDUP(MONTH(A3285)/3,0) -> Q4 | F3285: =TEXT(A3285,"yyyy-mmm") -> 2018-Dec | G3285: =WEEKDAY(A3285,2) -> 5 | H3285: =TEXT(A3285,"dddd") -> Friday | I3285: ="FM"&MOD(MONTH(A3285)-4,12)+1 -> FM9 | J3285: ="FQ-" & INT((MOD(MONTH(A3285)-4,12)/3)+1) -> FQ-3
A3286: =IF($O$1+ROW(A3285)-1<=$O$3,$O$1+ROW(A3285)-1,"")
A3288: =IF($O$1+ROW(A3287)-1<=$O$3,$O$1+ROW(A3287)-1,"")
A3289: =IF($O$1+ROW(A3288)-1<=$O$3,$O$1+ROW(A3288)-1,"")
A3290: =IF($O$1+ROW(A3289)-1<=$O$3,$O$1+ROW(A3289)-1,"")
A3291: =IF($O$1+ROW(A3290)-1<=$O$3,$O$1+ROW(A3290)-1,"")
A3292: =IF($O$1+ROW(A3291)-1<=$O$3,$O$1+ROW(A3291)-1,"")
A3293: =IF($O$1+ROW(A3292)-1<=$O$3,$O$1+ROW(A3292)-1,"")
A3294: =IF($O$1+ROW(A3293)-1<=$O$3,$O$1+ROW(A3293)-1,"")
A3295: =IF($O$1+ROW(A3294)-1<=$O$3,$O$1+ROW(A3294)-1,"")
A3296: =IF($O$1+ROW(A3295)-1<=$O$3,$O$1+ROW(A3295)-1,"")
A3297: =IF($O$1+ROW(A3296)-1<=$O$3,$O$1+ROW(A3296)-1,"")
A3298: =IF($O$1+ROW(A3297)-1<=$O$3,$O$1+ROW(A3297)-1,"")
... A4494: =IF($O$1+ROW(A4493)-1<=$O$3,$O$1+ROW(A4493)-1,"")

Sheet 4
A3: Row Labels | B3: Count of RestaurantID
A4: Australia | B4: 24
A5: Brazil | B5: 60
A6: Canada | B6: 4
A7: India | B7: 8652
A8: Indonasia | B8: 21
A9: New Zealand | B9: 40
A10: Phillipines | B10: 22
A11: Qatar | B11: 20
A12: Singapore | B12: 20
A13: South Africa | B13: 60
A14: Sri lanka | B14: 20
A15: Turkey | B15: 34
... A19: Grand Total | B19: 9551

Sheet 5
A3: Row Labels | B3: Count of RestaurantID
A4: 2010 | B4: 1080
A5: 2011 | B5: 1098
A6: 2012 | B6: 1022
A7: 2013 | B7: 1061
A8: 2014 | B8: 1051
A9: 2015 | B9: 1024
A10: 2016 | B10: 1027
A11: 2017 | B11: 1086
A12: 2018 | B12: 1102
A13: Grand Total | B13: 9551

Sheet 6
A3: Average Ratings | B3: Count of RestaurantID
A4: 4.5 | B4: 95
A5: 4.6 | B5: 78
A6: 4.9 | B6: 61
A7: 4.7 | B7: 42
A8: 4.8 | B8: 25
A9: Grand Total | B9: 301

Sheet 7
A3: Row Labels | B3: Count of RestaurantID
A4: High | B4: 0.06114543
A5: Low | B5: 0.54172338
A6: Medium | B6: 0.39713119
A7: Grand Total | B7: 1

Sheet 8
A3: Row Labels | B3: Count of RestaurantID
A4: No | B4: 0.87875615
A5: Yes | B5: 0.12124385
A6: Grand Total | B6: 1

Sheet 9
A3: Has_Online_delivery | B3: Count of RestaurantName
A4: No | B4: 0.74337766
A5: Yes | B5: 0.25662234
A6: Grand Total | B6: 1

Sheet Q 10; City
A3: City | B3: Average of Average_Cost_for_two
A4: Jakarta | B4: 308437.5
A5: Tangerang | B5: 250000
A6: Bogor | B6: 160000
A7: Bandung | B7: 150000
A8: Colombo | B8: 2375
A9: Pune | B9: 1337.5
A10: Gurgaon | B10: 714.0161
A11: New Delhi | B11: 596.08807
A12: Noida | B12: 539.49074
A13: Faridabad | B13: 447.60956
A14: Grand Total | B14: 1344.7213

Sheet Q 10; Cuisines
A3: Cuisines | B3: Count of RestaurantID
A4: North Indian | B4: 936
A5: North Indian, Chinese | B5: 511
A6: Fast Food | B6: 354
A7: Chinese | B7: 354
A8: North Indian, Mughlai | B8: 334
A9: Grand Total | B9: 2489

Sheet 10Rating
A3: Average of Rating | B3: Distinct Count of City | C3: Distinct Count of countryname
A4: 2.8912679 | B4: 142 | C4: 16
A6: ='10Rating'!A$4 -> 2.8912679 | B6: ='10Rating'!B$4 -> 142 | C6: ='10Rating'!C$4 -> 16

Sheet Dashboard
